<?xml version="1.0" ?>
<!-- =================================================================================== -->
<!-- |    This document was autogenerated by xacro from /home/xuanqi/test_mini/src/legged_control/legged_examples/sirius_robot/legged_sirius_description/urdf/robot.xacro | -->
<!-- |    EDITING THIS FILE BY HAND IS NOT RECOMMENDED                                 | -->
<!-- =================================================================================== -->
<robot name="robot">
  <material name="black">
    <color rgba="0.0 0.0 0.0 1.0"/>
  </material>
  <material name="blue">
    <color rgba="0.0 0.0 0.8 1.0"/>
  </material>
  <material name="green">
    <color rgba="0.0 0.8 0.0 1.0"/>
  </material>
  <material name="grey">
    <color rgba="0.2 0.2 0.2 1.0"/>
  </material>
  <material name="silver">
    <color rgba="0.9137254901960784 0.9137254901960784 0.8470588235294118 1.0"/>
  </material>
  <material name="orange">
    <color rgba="1.0 0.4235294117647059 0.0392156862745098 1.0"/>
  </material>
  <material name="brown">
    <color rgba="0.8705882352941177 0.8117647058823529 0.7647058823529411 1.0"/>
  </material>
  <material name="red">
    <color rgba="0.8 0.0 0.0 1.0"/>
  </material>
  <material name="white">
    <color rgba="1.0 1.0 1.0 1.0"/>
  </material>
  <!-- ros_control plugin -->
  <gazebo>
    <plugin filename="liblegged_hw_sim.so" name="gazebo_ros_control">
      <robotNamespace>/</robotNamespace>
      <robotParam>legged_robot_description</robotParam>
      <robotSimType>legged_gazebo/LeggedHWSim</robotSimType>
    </plugin>
  </gazebo>
  <!-- <gazebo>
    <plugin filename="libgazebo_ros_control.so" name="gazebo_ros_control">
      <robotNamespace>/legged_arm_control</robotNamespace>
      <robotSimType>gazebo_ros_control/DefaultRobotHWSim</robotSimType>
    </plugin>
  </gazebo> -->
  <gazebo>
    <plugin filename="libgazebo_ros_p3d.so" name="p3d_base_controller">
      <alwaysOn>true</alwaysOn>
      <updateRate>1000.0</updateRate>
      <bodyName>base</bodyName>
      <topicName>ground_truth/state</topicName>
      <gaussianNoise>0</gaussianNoise>
      <frameName>world</frameName>
      <xyzOffsets>0 0 0</xyzOffsets>
      <rpyOffsets>0 0 0</rpyOffsets>
    </plugin>
  </gazebo>
  <gazebo reference="base">
    <gravity>true</gravity>
    <sensor name="imu_sensor" type="imu">
      <always_on>true</always_on>
      <update_rate>1000</update_rate>
      <visualize>true</visualize>
      <topic>__default_topic__</topic>
      <plugin filename="libgazebo_ros_imu_sensor.so" name="imu_plugin">
        <topicName>imu</topicName>
        <bodyName>base</bodyName>
        <updateRateHZ>1000.0</updateRateHZ>
        <gaussianNoise>0.0</gaussianNoise>
        <xyzOffset>0 0 0</xyzOffset>
        <rpyOffset>0 0 0</rpyOffset>
        <frameName>base</frameName>
        <initialOrientationAsReference>false</initialOrientationAsReference>
      </plugin>
      <pose>0 0 0 0 0 0</pose>
    </sensor>
  </gazebo>
  <link name="base">
    <visual>
      <origin rpy="0 0 0" xyz="0 0 0"/>
      <geometry>
        <mesh filename="package://legged_sirius_description/meshes/sirius_mini/trunk.STL" scale="1 1 1"/>
        <!-- <box size="0.27 0.15 0.1"/> -->
      </geometry>
    </visual>
    <collision>
      <origin rpy="0 0 0" xyz="0 0 0"/>
      <geometry>
        <box size="0.27 0.15 0.1"/>
      </geometry>
    </collision>
    <inertial>
      <origin rpy="0 0 0" xyz="0.0 0.0041 -0.0005"/>
      <mass value="6.0"/>
      <inertia ixx="0.0112533" ixy="-3.66e-05" ixz="-6.11e-05" iyy="0.0362" iyz="-2.75e-05" izz="0.042673"/>
    </inertial>
  </link>
  <!-- Imu is fixed to the base link -->
  <joint name="unitree_imu_joint" type="fixed">
    <origin rpy="0. 0. 0." xyz="0. 0. 0."/>
    <parent link="base"/>
    <child link="unitree_imu"/>
  </joint>
  <!-- Imu link -->
  <link name="unitree_imu">
    <inertial>
      <mass value="0.01"/>
      <origin rpy="0 0 0" xyz="0 0 0"/>
      <inertia ixx="0.000001" ixy="0" ixz="0" iyy="0.000001" iyz="0" izz="0.000001"/>
    </inertial>
    <visual>
      <origin rpy="0 0 0" xyz="0 0 0"/>
      <geometry>
        <box size="0.015 0.015 0.004"/>
      </geometry>
    </visual>
    <material name="orange">
      <color rgba="255 108 10 255"/>
    </material>
  </link>
  <gazebo reference="unitree_imu">
    <material>Gazebo/Orange</material>
  </gazebo>
  <gazebo reference="unitree_imu_joint">
    <disableFixedJointLumping>true</disableFixedJointLumping>
  </gazebo>
  <joint name="RF_HAA" type="revolute">
    <origin rpy="0 0 0" xyz="0.195 -0.05 0"/>
    <parent link="base"/>
    <child link="RF_hip"/>
    <axis xyz="1 0 0"/>
    <dynamics damping="0.01" friction="0.1"/>
    <limit effort="24" lower="-1.4835298641951802" upper="1.4835298641951802" velocity="45"/>
  </joint>
  <link name="RF_hip">
    <visual>
      <origin rpy="0 3.141592653589793 0" xyz="0 0 0"/>
      <!-- <origin rpy="1.5707963267948966 0 0" xyz="0 0 0"/> -->
      <geometry>
        <mesh filename="package://legged_sirius_description/meshes/sirius_mini/hip.STL" scale="1 1 1"/>
        <!-- <cylinder length="0.04" radius="0.046"/> -->
      </geometry>
      <material name="orange"/>
    </visual>
    <collision>
      <origin rpy="1.5707963267948966 0 0" xyz="0 0 0"/>
      <geometry>
        <cylinder length="0.04" radius="0.046"/>
      </geometry>
    </collision>
    <inertial>
      <origin rpy="0 0 0" xyz="-0.003875 -0.001622 4.2e-05"/>
      <mass value="0.575"/>
      <inertia ixx="0.000402747" ixy="8.709e-06" ixz="-2.97e-07" iyy="0.000691123" iyz="5.45e-07" izz="0.000487919"/>
    </inertial>
  </link>
  <joint name="RF_HFE" type="revolute">
    <origin rpy="0 0 0" xyz="0.0 -0.072 0"/>
    <parent link="RF_hip"/>
    <child link="RF_thigh"/>
    <axis xyz="0 1 0"/>
    <dynamics damping="0.01" friction="0.1"/>
    <limit effort="24" lower="-1.7453292519943295" upper="2.0943951023931953" velocity="45"/>
  </joint>
  <link name="RF_thigh">
    <visual>
      <origin rpy="0 0 0" xyz="0 0 0"/>
      <!-- <origin rpy="0 1.6707963267948966 0" xyz="0 0 -0.105"/> -->
      <geometry>
        <mesh filename="package://legged_sirius_description/meshes/sirius_mini/thigh.STL" scale="1 1 1"/>
        <!-- <box size="0.21 0.03 0.034"/> -->
      </geometry>
      <material name="orange"/>
    </visual>
    <collision>
      <origin rpy="0 1.6707963267948966 0" xyz="0 0 -0.105"/>
      <geometry>
        <box size="0.21 0.03 0.034"/>
      </geometry>
    </collision>
    <collision>
      <origin rpy="1.5707963267948966 0 0" xyz="0 0.0 0"/>
      <geometry>
        <cylinder length="0.04" radius="0.041"/>
      </geometry>
    </collision>
    <inertial>
      <origin rpy="0 0 0" xyz="-0.003574 0.019529 -0.030323"/>
      <mass value="0.634"/>
      <inertia ixx="0.005251806" ixy="2.168e-06" ixz="0.000346889" iyy="0.005000475" iyz="2.8174e-05" izz="0.0011102"/>
    </inertial>
  </link>
  <joint name="RF_KFE" type="revolute">
    <origin rpy="0 0 0" xyz="0 0 -0.21"/>
    <parent link="RF_thigh"/>
    <child link="RF_calf"/>
    <axis xyz="0 1 0"/>
    <dynamics damping="0.01" friction="0.1"/>
    <limit effort="36" lower="-3.141592653589793" upper="0.3490658503988659" velocity="45"/>
  </joint>
  <link name="RF_calf">
    <visual>
      <origin rpy="0 0 0" xyz="0 0.01 0"/>
      <!-- <origin rpy="0 1.5707963267948966 0" xyz="0 0 -0.1"/> -->
      <geometry>
        <mesh filename="package://legged_sirius_description/meshes/sirius_mini/calf.STL" scale="1 1 1"/>
        <!-- <box size="0.2 0.016 0.016"/> -->
      </geometry>
      <material name="orange"/>
    </visual>
    <collision>
      <origin rpy="0 1.5707963267948966 0" xyz="0 0 -0.1"/>
      <geometry>
        <box size="0.2 0.016 0.016"/>
      </geometry>
    </collision>
    <inertial>
      <origin rpy="0 0 0" xyz="0.007105 -0.000239 -0.096933"/>
      <mass value="0.151"/>
      <inertia ixx="0.002344758" ixy="0.0" ixz="-0.000141275" iyy="0.002360755" iyz="0.0" izz="3.1158e-05"/>
    </inertial>
  </link>
  <joint name="RF_foot_fixed" type="fixed">
    <origin rpy="0 0 0" xyz="0 0 -0.2"/>
    <parent link="RF_calf"/>
    <child link="RF_FOOT"/>
  </joint>
  <link name="RF_FOOT">
    <visual>
      <origin rpy="0 0 0" xyz="0 0 0"/>
      <geometry>
        <sphere radius="0.02"/>
      </geometry>
      <material name="orange"/>
    </visual>
    <collision>
      <origin rpy="0 0 0" xyz="0 0 0"/>
      <geometry>
        <sphere radius="0.02"/>
      </geometry>
    </collision>
    <inertial>
      <mass value="0.06"/>
      <inertia ixx="9.600000000000001e-06" ixy="0.0" ixz="0.0" iyy="9.600000000000001e-06" iyz="0.0" izz="9.600000000000001e-06"/>
    </inertial>
  </link>
  <gazebo reference="RF_foot_fixed">
    <disableFixedJointLumping>true</disableFixedJointLumping>
  </gazebo>
  <gazebo reference="RF_hip">
    <mu1>0.2</mu1>
    <mu2>0.2</mu2>
    <material>Gazebo/DarkGrey</material>
  </gazebo>
  <gazebo reference="RF_thigh">
    <mu1>0.2</mu1>
    <mu2>0.2</mu2>
    <self_collide>0</self_collide>
    <material>Gazebo/DarkGrey</material>
    <kp value="1000000.0"/>
    <kd value="100.0"/>
  </gazebo>
  <gazebo reference="RF_calf">
    <mu1>0.6</mu1>
    <mu2>0.6</mu2>
    <self_collide>1</self_collide>
  </gazebo>
  <gazebo reference="RF_FOOT">
    <mu1>0.6</mu1>
    <mu2>0.6</mu2>
    <self_collide>1</self_collide>
    <material>Gazebo/DarkGrey</material>
    <kp value="1000000.0"/>
    <kd value="100.0"/>
  </gazebo>
  <transmission name="RF_HAA_tran">
    <type>transmission_interface/SimpleTransmission</type>
    <joint name="RF_HAA">
      <hardwareInterface>hardware_interface/EffortJointInterface</hardwareInterface>
    </joint>
    <actuator name="RF_HAA_motor">
      <hardwareInterface>hardware_interface/EffortJointInterface</hardwareInterface>
      <mechanicalReduction>1</mechanicalReduction>
    </actuator>
  </transmission>
  <transmission name="RF_HFE_tran">
    <type>transmission_interface/SimpleTransmission</type>
    <joint name="RF_HFE">
      <hardwareInterface>hardware_interface/EffortJointInterface</hardwareInterface>
    </joint>
    <actuator name="RF_HFE_motor">
      <hardwareInterface>hardware_interface/EffortJointInterface</hardwareInterface>
      <mechanicalReduction>1</mechanicalReduction>
    </actuator>
  </transmission>
  <transmission name="RF_KFE_tran">
    <type>transmission_interface/SimpleTransmission</type>
    <joint name="RF_KFE">
      <hardwareInterface>hardware_interface/EffortJointInterface</hardwareInterface>
    </joint>
    <actuator name="RF_KFE_motor">
      <hardwareInterface>hardware_interface/EffortJointInterface</hardwareInterface>
      <mechanicalReduction>1</mechanicalReduction>
    </actuator>
  </transmission>
  <joint name="LF_HAA" type="revolute">
    <origin rpy="0 0 0" xyz="0.195 0.05 0"/>
    <parent link="base"/>
    <child link="LF_hip"/>
    <axis xyz="1 0 0"/>
    <dynamics damping="0.01" friction="0.1"/>
    <limit effort="24" lower="-1.4835298641951802" upper="1.4835298641951802" velocity="45"/>
  </joint>
  <link name="LF_hip">
    <visual>
      <origin rpy="3.141592653589793 3.141592653589793 0" xyz="0 0 0"/>
      <!-- <origin rpy="1.5707963267948966 0 0" xyz="0 0 0"/> -->
      <geometry>
        <mesh filename="package://legged_sirius_description/meshes/sirius_mini/hip.STL" scale="1 1 1"/>
        <!-- <cylinder length="0.04" radius="0.046"/> -->
      </geometry>
      <material name="orange"/>
    </visual>
    <collision>
      <origin rpy="1.5707963267948966 0 0" xyz="0 0 0"/>
      <geometry>
        <cylinder length="0.04" radius="0.046"/>
      </geometry>
    </collision>
    <inertial>
      <origin rpy="0 0 0" xyz="-0.003875 0.001622 4.2e-05"/>
      <mass value="0.575"/>
      <inertia ixx="0.000402747" ixy="-8.709e-06" ixz="-2.97e-07" iyy="0.000691123" iyz="-5.45e-07" izz="0.000487919"/>
    </inertial>
  </link>
  <joint name="LF_HFE" type="revolute">
    <origin rpy="0 0 0" xyz="0.0 0.072 0"/>
    <parent link="LF_hip"/>
    <child link="LF_thigh"/>
    <axis xyz="0 1 0"/>
    <dynamics damping="0.01" friction="0.1"/>
    <limit effort="24" lower="-1.7453292519943295" upper="2.0943951023931953" velocity="45"/>
  </joint>
  <link name="LF_thigh">
    <visual>
      <origin rpy="3.141592653589793 3.141592653589793 0" xyz="0 0 0"/>
      <!-- <origin rpy="0 1.6707963267948966 0" xyz="0 0 -0.105"/> -->
      <geometry>
        <mesh filename="package://legged_sirius_description/meshes/sirius_mini/thigh_mirror.STL" scale="1 1 1"/>
        <!-- <box size="0.21 0.03 0.034"/> -->
      </geometry>
      <material name="orange"/>
    </visual>
    <collision>
      <!-- <origin rpy="0 1.6707963267948966 0" xyz="0 0 -0.105"/> -->
      <geometry>
        <box size="0.21 0.03 0.034"/>
      </geometry>
    </collision>
    <collision>
      <origin rpy="1.5707963267948966 0 0" xyz="0 -0.0 0"/>
      <geometry>
        <cylinder length="0.04" radius="0.041"/>
      </geometry>
    </collision>
    <inertial>
      <origin rpy="0 0 0" xyz="-0.003574 -0.019529 -0.030323"/>
      <mass value="0.634"/>
      <inertia ixx="0.005251806" ixy="-2.168e-06" ixz="0.000346889" iyy="0.005000475" iyz="-2.8174e-05" izz="0.0011102"/>
    </inertial>
  </link>
  <joint name="LF_KFE" type="revolute">
    <origin rpy="0 0 0" xyz="0 0 -0.21"/>
    <parent link="LF_thigh"/>
    <child link="LF_calf"/>
    <axis xyz="0 1 0"/>
    <dynamics damping="0.01" friction="0.1"/>
    <limit effort="36" lower="-3.141592653589793" upper="0.3490658503988659" velocity="45"/>
  </joint>
  <link name="LF_calf">
    <visual>
      <origin rpy="0 0 0" xyz="0 0.01 0"/>
      <!-- <origin rpy="0 1.5707963267948966 0" xyz="0 0 -0.1"/> -->
      <geometry>
        <mesh filename="package://legged_sirius_description/meshes/sirius_mini/calf.STL" scale="1 1 1"/>
        <!-- <box size="0.2 0.016 0.016"/> -->
      </geometry>
      <material name="orange"/>
    </visual>
    <collision>
      <origin rpy="0 1.5707963267948966 0" xyz="0 0 -0.1"/>
      <geometry>
        <box size="0.2 0.016 0.016"/>
      </geometry>
    </collision>
    <inertial>
      <origin rpy="0 0 0" xyz="0.007105 -0.000239 -0.096933"/>
      <mass value="0.151"/>
      <inertia ixx="0.002344758" ixy="0.0" ixz="-0.000141275" iyy="0.002360755" iyz="0.0" izz="3.1158e-05"/>
    </inertial>
  </link>
  <joint name="LF_foot_fixed" type="fixed">
    <origin rpy="0 0 0" xyz="0 0 -0.2"/>
    <parent link="LF_calf"/>
    <child link="LF_FOOT"/>
  </joint>
  <link name="LF_FOOT">
    <visual>
      <origin rpy="0 0 0" xyz="0 0 0"/>
      <geometry>
        <sphere radius="0.02"/>
      </geometry>
      <material name="orange"/>
    </visual>
    <collision>
      <origin rpy="0 0 0" xyz="0 0 0"/>
      <geometry>
        <sphere radius="0.02"/>
      </geometry>
    </collision>
    <inertial>
      <mass value="0.06"/>
      <inertia ixx="9.600000000000001e-06" ixy="0.0" ixz="0.0" iyy="9.600000000000001e-06" iyz="0.0" izz="9.600000000000001e-06"/>
    </inertial>
  </link>
  <gazebo reference="LF_foot_fixed">
    <disableFixedJointLumping>true</disableFixedJointLumping>
  </gazebo>
  <gazebo reference="LF_hip">
    <mu1>0.2</mu1>
    <mu2>0.2</mu2>
    <material>Gazebo/DarkGrey</material>
  </gazebo>
  <gazebo reference="LF_thigh">
    <mu1>0.2</mu1>
    <mu2>0.2</mu2>
    <self_collide>0</self_collide>
    <material>Gazebo/DarkGrey</material>
    <kp value="1000000.0"/>
    <kd value="100.0"/>
  </gazebo>
  <gazebo reference="LF_calf">
    <mu1>0.6</mu1>
    <mu2>0.6</mu2>
    <self_collide>1</self_collide>
  </gazebo>
  <gazebo reference="LF_FOOT">
    <mu1>0.6</mu1>
    <mu2>0.6</mu2>
    <self_collide>1</self_collide>
    <material>Gazebo/DarkGrey</material>
    <kp value="1000000.0"/>
    <kd value="100.0"/>
  </gazebo>
  <transmission name="LF_HAA_tran">
    <type>transmission_interface/SimpleTransmission</type>
    <joint name="LF_HAA">
      <hardwareInterface>hardware_interface/EffortJointInterface</hardwareInterface>
    </joint>
    <actuator name="LF_HAA_motor">
      <hardwareInterface>hardware_interface/EffortJointInterface</hardwareInterface>
      <mechanicalReduction>1</mechanicalReduction>
    </actuator>
  </transmission>
  <transmission name="LF_HFE_tran">
    <type>transmission_interface/SimpleTransmission</type>
    <joint name="LF_HFE">
      <hardwareInterface>hardware_interface/EffortJointInterface</hardwareInterface>
    </joint>
    <actuator name="LF_HFE_motor">
      <hardwareInterface>hardware_interface/EffortJointInterface</hardwareInterface>
      <mechanicalReduction>1</mechanicalReduction>
    </actuator>
  </transmission>
  <transmission name="LF_KFE_tran">
    <type>transmission_interface/SimpleTransmission</type>
    <joint name="LF_KFE">
      <hardwareInterface>hardware_interface/EffortJointInterface</hardwareInterface>
    </joint>
    <actuator name="LF_KFE_motor">
      <hardwareInterface>hardware_interface/EffortJointInterface</hardwareInterface>
      <mechanicalReduction>1</mechanicalReduction>
    </actuator>
  </transmission>
  <joint name="RH_HAA" type="revolute">
    <origin rpy="0 0 0" xyz="-0.195 -0.05 0"/>
    <parent link="base"/>
    <child link="RH_hip"/>
    <axis xyz="1 0 0"/>
    <dynamics damping="0.01" friction="0.1"/>
    <limit effort="24" lower="-1.4835298641951802" upper="1.4835298641951802" velocity="45"/>
  </joint>
  <link name="RH_hip">
    <visual>
      <origin rpy="0 0 0" xyz="0 0 0"/>
      <!-- <origin rpy="1.5707963267948966 0 0" xyz="0 0 0"/> -->
      <geometry>
        <mesh filename="package://legged_sirius_description/meshes/sirius_mini/hip.STL" scale="1 1 1"/>
        <!-- <cylinder length="0.04" radius="0.046"/> -->
      </geometry>
      <material name="orange"/>
    </visual>
    <collision>
      <origin rpy="1.5707963267948966 0 0" xyz="0 0 0"/>
      <geometry>
        <cylinder length="0.04" radius="0.046"/>
      </geometry>
    </collision>
    <inertial>
      <origin rpy="0 0 0" xyz="0.003875 -0.001622 4.2e-05"/>
      <mass value="0.575"/>
      <inertia ixx="0.000402747" ixy="-8.709e-06" ixz="2.97e-07" iyy="0.000691123" iyz="5.45e-07" izz="0.000487919"/>
    </inertial>
  </link>
  <joint name="RH_HFE" type="revolute">
    <origin rpy="0 0 0" xyz="-0.0 -0.072 0"/>
    <parent link="RH_hip"/>
    <child link="RH_thigh"/>
    <axis xyz="0 1 0"/>
    <dynamics damping="0.01" friction="0.1"/>
    <limit effort="24" lower="-1.7453292519943295" upper="2.0943951023931953" velocity="45"/>
  </joint>
  <link name="RH_thigh">
    <visual>
      <origin rpy="0 0 0" xyz="0 0 0"/>
      <!-- <origin rpy="0 1.6707963267948966 0" xyz="0 0 -0.105"/> -->
      <geometry>
        <mesh filename="package://legged_sirius_description/meshes/sirius_mini/thigh.STL" scale="1 1 1"/>
        <!-- <box size="0.21 0.03 0.034"/> -->
      </geometry>
      <material name="orange"/>
    </visual>
    <collision>
      <origin rpy="0 1.6707963267948966 0" xyz="0 0 -0.105"/>
      <geometry>
        <box size="0.21 0.03 0.034"/>
      </geometry>
    </collision>
    <collision>
      <origin rpy="1.5707963267948966 0 0" xyz="0 0.0 0"/>
      <geometry>
        <cylinder length="0.04" radius="0.041"/>
      </geometry>
    </collision>
    <inertial>
      <origin rpy="0 0 0" xyz="-0.003574 0.019529 -0.030323"/>
      <mass value="0.634"/>
      <inertia ixx="0.005251806" ixy="2.168e-06" ixz="0.000346889" iyy="0.005000475" iyz="2.8174e-05" izz="0.0011102"/>
    </inertial>
  </link>
  <joint name="RH_KFE" type="revolute">
    <origin rpy="0 0 0" xyz="0 0 -0.21"/>
    <parent link="RH_thigh"/>
    <child link="RH_calf"/>
    <axis xyz="0 1 0"/>
    <dynamics damping="0.01" friction="0.1"/>
    <limit effort="36" lower="-3.141592653589793" upper="0.3490658503988659" velocity="45"/>
  </joint>
  <link name="RH_calf">
    <visual>
      <origin rpy="0 0 0" xyz="0 0.01 0"/>
      <!-- <origin rpy="0 1.5707963267948966 0" xyz="0 0 -0.1"/> -->
      <geometry>
        <mesh filename="package://legged_sirius_description/meshes/sirius_mini/calf.STL" scale="1 1 1"/>
        <!-- <box size="0.2 0.016 0.016"/> -->
      </geometry>
      <material name="orange"/>
    </visual>
    <collision>
      <origin rpy="0 1.5707963267948966 0" xyz="0 0 -0.1"/>
      <geometry>
        <box size="0.2 0.016 0.016"/>
      </geometry>
    </collision>
    <inertial>
      <origin rpy="0 0 0" xyz="0.007105 -0.000239 -0.096933"/>
      <mass value="0.151"/>
      <inertia ixx="0.002344758" ixy="0.0" ixz="-0.000141275" iyy="0.002360755" iyz="0.0" izz="3.1158e-05"/>
    </inertial>
  </link>
  <joint name="RH_foot_fixed" type="fixed">
    <origin rpy="0 0 0" xyz="0 0 -0.2"/>
    <parent link="RH_calf"/>
    <child link="RH_FOOT"/>
  </joint>
  <link name="RH_FOOT">
    <visual>
      <origin rpy="0 0 0" xyz="0 0 0"/>
      <geometry>
        <sphere radius="0.02"/>
      </geometry>
      <material name="orange"/>
    </visual>
    <collision>
      <origin rpy="0 0 0" xyz="0 0 0"/>
      <geometry>
        <sphere radius="0.02"/>
      </geometry>
    </collision>
    <inertial>
      <mass value="0.06"/>
      <inertia ixx="9.600000000000001e-06" ixy="0.0" ixz="0.0" iyy="9.600000000000001e-06" iyz="0.0" izz="9.600000000000001e-06"/>
    </inertial>
  </link>
  <gazebo reference="RH_foot_fixed">
    <disableFixedJointLumping>true</disableFixedJointLumping>
  </gazebo>
  <gazebo reference="RH_hip">
    <mu1>0.2</mu1>
    <mu2>0.2</mu2>
    <material>Gazebo/DarkGrey</material>
  </gazebo>
  <gazebo reference="RH_thigh">
    <mu1>0.2</mu1>
    <mu2>0.2</mu2>
    <self_collide>0</self_collide>
    <material>Gazebo/DarkGrey</material>
    <kp value="1000000.0"/>
    <kd value="100.0"/>
  </gazebo>
  <gazebo reference="RH_calf">
    <mu1>0.6</mu1>
    <mu2>0.6</mu2>
    <self_collide>1</self_collide>
  </gazebo>
  <gazebo reference="RH_FOOT">
    <mu1>0.6</mu1>
    <mu2>0.6</mu2>
    <self_collide>1</self_collide>
    <material>Gazebo/DarkGrey</material>
    <kp value="1000000.0"/>
    <kd value="100.0"/>
  </gazebo>
  <transmission name="RH_HAA_tran">
    <type>transmission_interface/SimpleTransmission</type>
    <joint name="RH_HAA">
      <hardwareInterface>hardware_interface/EffortJointInterface</hardwareInterface>
    </joint>
    <actuator name="RH_HAA_motor">
      <hardwareInterface>hardware_interface/EffortJointInterface</hardwareInterface>
      <mechanicalReduction>1</mechanicalReduction>
    </actuator>
  </transmission>
  <transmission name="RH_HFE_tran">
    <type>transmission_interface/SimpleTransmission</type>
    <joint name="RH_HFE">
      <hardwareInterface>hardware_interface/EffortJointInterface</hardwareInterface>
    </joint>
    <actuator name="RH_HFE_motor">
      <hardwareInterface>hardware_interface/EffortJointInterface</hardwareInterface>
      <mechanicalReduction>1</mechanicalReduction>
    </actuator>
  </transmission>
  <transmission name="RH_KFE_tran">
    <type>transmission_interface/SimpleTransmission</type>
    <joint name="RH_KFE">
      <hardwareInterface>hardware_interface/EffortJointInterface</hardwareInterface>
    </joint>
    <actuator name="RH_KFE_motor">
      <hardwareInterface>hardware_interface/EffortJointInterface</hardwareInterface>
      <mechanicalReduction>1</mechanicalReduction>
    </actuator>
  </transmission>
  <joint name="LH_HAA" type="revolute">
    <origin rpy="0 0 0" xyz="-0.195 0.05 0"/>
    <parent link="base"/>
    <child link="LH_hip"/>
    <axis xyz="1 0 0"/>
    <dynamics damping="0.01" friction="0.1"/>
    <limit effort="24" lower="-1.4835298641951802" upper="1.4835298641951802" velocity="45"/>
  </joint>
  <link name="LH_hip">
    <visual>
      <origin rpy="3.141592653589793 0 0" xyz="0 0 0"/>
      <!-- <origin rpy="1.5707963267948966 0 0" xyz="0 0 0"/> -->
      <geometry>
        <mesh filename="package://legged_sirius_description/meshes/sirius_mini/hip.STL" scale="1 1 1"/>
        <!-- <cylinder length="0.04" radius="0.046"/> -->
      </geometry>
      <material name="orange"/>
    </visual>
    <collision>
      <origin rpy="1.5707963267948966 0 0" xyz="0 0 0"/>
      <geometry>
        <cylinder length="0.04" radius="0.046"/>
      </geometry>
    </collision>
    <inertial>
      <origin rpy="0 0 0" xyz="0.003875 0.001622 4.2e-05"/>
      <mass value="0.575"/>
      <inertia ixx="0.000402747" ixy="8.709e-06" ixz="2.97e-07" iyy="0.000691123" iyz="-5.45e-07" izz="0.000487919"/>
    </inertial>
  </link>
  <joint name="LH_HFE" type="revolute">
    <origin rpy="0 0 0" xyz="-0.0 0.072 0"/>
    <parent link="LH_hip"/>
    <child link="LH_thigh"/>
    <axis xyz="0 1 0"/>
    <dynamics damping="0.01" friction="0.1"/>
    <limit effort="24" lower="-1.7453292519943295" upper="2.0943951023931953" velocity="45"/>
  </joint>
  <link name="LH_thigh">
    <visual>
      <origin rpy="3.141592653589793 3.141592653589793 0" xyz="0 0 0"/>
      <!-- <origin rpy="0 1.6707963267948966 0" xyz="0 0 -0.105"/> -->
      <geometry>
        <mesh filename="package://legged_sirius_description/meshes/sirius_mini/thigh_mirror.STL" scale="1 1 1"/>
        <!-- <box size="0.21 0.03 0.034"/> -->
      </geometry>
      <material name="orange"/>
    </visual>
    <collision>
      <origin rpy="0 1.6707963267948966 0" xyz="0 0 -0.105"/>
      <geometry>
        <box size="0.21 0.03 0.034"/>
      </geometry>
    </collision>
    <collision>
      <origin rpy="1.5707963267948966 0 0" xyz="0 -0.0 0"/>
      <geometry>
        <cylinder length="0.04" radius="0.041"/>
      </geometry>
    </collision>
    <inertial>
      <origin rpy="0 0 0" xyz="-0.003574 -0.019529 -0.030323"/>
      <mass value="0.634"/>
      <inertia ixx="0.005251806" ixy="-2.168e-06" ixz="0.000346889" iyy="0.005000475" iyz="-2.8174e-05" izz="0.0011102"/>
    </inertial>
  </link>
  <joint name="LH_KFE" type="revolute">
    <origin rpy="0 0 0" xyz="0 0 -0.21"/>
    <parent link="LH_thigh"/>
    <child link="LH_calf"/>
    <axis xyz="0 1 0"/>
    <dynamics damping="0.01" friction="0.1"/>
    <limit effort="36" lower="-3.141592653589793" upper="0.3490658503988659" velocity="45"/>
  </joint>
  <link name="LH_calf">
    <visual>
      <origin rpy="0 0 0" xyz="0 0.01 0"/>
      <!-- <origin rpy="0 1.5707963267948966 0" xyz="0 0 -0.1"/> -->
      <geometry>
        <mesh filename="package://legged_sirius_description/meshes/sirius_mini/calf.STL" scale="1 1 1"/>
        <!-- <box size="0.2 0.016 0.016"/> -->
      </geometry>
      <material name="orange"/>
    </visual>
    <collision>
      <origin rpy="0 1.5707963267948966 0" xyz="0 0 -0.1"/>
      <geometry>
        <box size="0.2 0.016 0.016"/>
      </geometry>
    </collision>
    <inertial>
      <origin rpy="0 0 0" xyz="0.007105 -0.000239 -0.096933"/>
      <mass value="0.151"/>
      <inertia ixx="0.002344758" ixy="0.0" ixz="-0.000141275" iyy="0.002360755" iyz="0.0" izz="3.1158e-05"/>
    </inertial>
  </link>
  <joint name="LH_foot_fixed" type="fixed">
    <origin rpy="0 0 0" xyz="0 0 -0.2"/>
    <parent link="LH_calf"/>
    <child link="LH_FOOT"/>
  </joint>
  <link name="LH_FOOT">
    <visual>
      <origin rpy="0 0 0" xyz="0 0 0"/>
      <geometry>
        <sphere radius="0.02"/>
      </geometry>
      <material name="orange"/>
    </visual>
    <collision>
      <origin rpy="0 0 0" xyz="0 0 0"/>
      <geometry>
        <sphere radius="0.02"/>
      </geometry>
    </collision>
    <inertial>
      <mass value="0.06"/>
      <inertia ixx="9.600000000000001e-06" ixy="0.0" ixz="0.0" iyy="9.600000000000001e-06" iyz="0.0" izz="9.600000000000001e-06"/>
    </inertial>
  </link>
  <gazebo reference="LH_foot_fixed">
    <disableFixedJointLumping>true</disableFixedJointLumping>
  </gazebo>
  <gazebo reference="LH_hip">
    <mu1>0.2</mu1>
    <mu2>0.2</mu2>
    <material>Gazebo/DarkGrey</material>
  </gazebo>
  <gazebo reference="LH_thigh">
    <mu1>0.2</mu1>
    <mu2>0.2</mu2>
    <self_collide>0</self_collide>
    <material>Gazebo/DarkGrey</material>
    <kp value="1000000.0"/>
    <kd value="100.0"/>
  </gazebo>
  <gazebo reference="LH_calf">
    <mu1>0.6</mu1>
    <mu2>0.6</mu2>
    <self_collide>1</self_collide>
  </gazebo>
  <gazebo reference="LH_FOOT">
    <mu1>0.6</mu1>
    <mu2>0.6</mu2>
    <self_collide>1</self_collide>
    <material>Gazebo/DarkGrey</material>
    <kp value="1000000.0"/>
    <kd value="100.0"/>
  </gazebo>
  <transmission name="LH_HAA_tran">
    <type>transmission_interface/SimpleTransmission</type>
    <joint name="LH_HAA">
      <hardwareInterface>hardware_interface/EffortJointInterface</hardwareInterface>
    </joint>
    <actuator name="LH_HAA_motor">
      <hardwareInterface>hardware_interface/EffortJointInterface</hardwareInterface>
      <mechanicalReduction>1</mechanicalReduction>
    </actuator>
  </transmission>
  <transmission name="LH_HFE_tran">
    <type>transmission_interface/SimpleTransmission</type>
    <joint name="LH_HFE">
      <hardwareInterface>hardware_interface/EffortJointInterface</hardwareInterface>
    </joint>
    <actuator name="LH_HFE_motor">
      <hardwareInterface>hardware_interface/EffortJointInterface</hardwareInterface>
      <mechanicalReduction>1</mechanicalReduction>
    </actuator>
  </transmission>
  <transmission name="LH_KFE_tran">
    <type>transmission_interface/SimpleTransmission</type>
    <joint name="LH_KFE">
      <hardwareInterface>hardware_interface/EffortJointInterface</hardwareInterface>
    </joint>
    <actuator name="LH_KFE_motor">
      <hardwareInterface>hardware_interface/EffortJointInterface</hardwareInterface>
      <mechanicalReduction>1</mechanicalReduction>
    </actuator>
  </transmission>
  <link
    name="base_link">
    <inertial>
      <origin
        xyz="-1.033E-05 0.00010225 -0.06559"
        rpy="0 0 0" />
      <mass
        value="0.40002" />
      <inertia
        ixx="0.00016697"
        ixy="1.1946E-07"
        ixz="-1.4819E-07"
        iyy="0.00016516"
        iyz="-2.1363E-07"
        izz="0.00019324" />
    </inertial>
    <visual>
      <origin
        xyz="0 0 0"
        rpy="0 0 0" />
      <!-- <origin
        xyz="0 0 -0.07"
        rpy="0 0 0" /> -->
      <geometry>
        <mesh
          filename="package://mini_tail_description/meshes/base_link.STL" />
          <!-- <cylinder length="0.06" radius="0.035"/> -->
      </geometry>
      <material
        name="">
        <color
          rgba="0.75294 0.75294 0.75294 1" />
      </material>
    </visual>
    <collision>
      <origin
        xyz="0 0 -0.07"
        rpy="0 0 0" />
      <geometry>
        <!-- <mesh
          filename="package://tail_urdf/meshes/base_link.STL" /> -->
        <cylinder length="0.06" radius="0.035"/>
      </geometry>
    </collision>
  </link>
  <joint name="base_base_link" type="fixed">
    <origin rpy="0. -1.57 0." xyz="0. 0. 0.08"/>
    <parent link="base"/>
    <child link="base_link"/>
  </joint>
  <link
    name="link1">
    <inertial>
      <origin
        xyz="0.00011758 0.037923 -0.0047736"
        rpy="0 0 0" />
      <mass
        value="0.33662" />
      <inertia
        ixx="0.000108"
        ixy="4.7926E-08"
        ixz="7.8305E-07"
        iyy="0.00010771"
        iyz="-2.8742E-06"
        izz="0.00011466" />
    </inertial>
    <visual>
      <origin
        xyz="0 0 0"
        rpy="0 0 0" />
      <geometry>
        <mesh
          filename="package://mini_tail_description/mini_tail_description/meshes/link1.STL" />
          <!-- <cylinder length="0.1" radius="0.01"/> -->
      </geometry>
      <material
        name="">
        <color
          rgba="0.75294 0.75294 0.75294 1" />
      </material>
    </visual>
    <collision>
      <origin
        xyz="0 0 0"
        rpy="0 0 0" />
      <geometry>
        <!-- <mesh
          filename="package://mini_tail_description/meshes/link1.STL" /> -->
          <cylinder length="0.1" radius="0.01"/>
      </geometry>
    </collision>
  </link>
  <joint
    name="joint1"
    type="revolute">
    <origin
      xyz="0 0 0"
      rpy="0 0 0" />
    <parent
      link="base_link" />
    <child
      link="link1" />
    <axis
      xyz="0 0 1" />
    <dynamics damping="0.01" friction="0.1"/>
    <limit
      lower="-3.14"
      upper="3.14"
      effort="8"
      velocity="12.57" />
  </joint>
  <link
    name="link2">
    <inertial>
      <origin
        xyz="-0.042582 -0.00064582 0.021089"
        rpy="0 0 0" />
      <mass
        value="0.51319" />
      <inertia
        ixx="0.00014058"
        ixy="4.3985E-09"
        ixz="2.7786E-06"
        iyy="0.00071518"
        iyz="1.726E-08"
        izz="0.00074558" />
    </inertial>
    <visual>
      <origin
        xyz="0 0 0"
        rpy="0 0 0" />
      <!-- <origin
        xyz="-0.1 0 0"
        rpy="0 1.57 0" /> -->
      <geometry>
        <mesh
          filename="package://mini_tail_description/meshes/link2.STL" />
        <!-- <cylinder length="0.23" radius="0.012"/> -->
      </geometry>
      <material
        name="">
        <color
          rgba="0.75294 0.75294 0.75294 1" />
      </material>
    </visual>
    <collision>
      <origin
        xyz="-0.1 0 0"
        rpy="0 1.57 0" />
      <geometry>
        <!-- <mesh
          filename="package://tail_urdf/meshes/link2.STL" /> -->
          <cylinder length="0.23" radius="0.012"/>
      </geometry>
    </collision>
  </link>
  <joint
    name="joint2"
    type="revolute">
    <origin
      xyz="0 0 0"
      rpy="1.5708 1.5708 0" />
    <parent
      link="link1" />
    <child
      link="link2" />
    <axis
      xyz="0 0 1" />
    <dynamics damping="0.01" friction="0.1"/>
    <limit
      lower="-3.14"
      upper="0"
      effort="8"
      velocity="12.57" />
  </joint>
  <link
    name="link3">
    <inertial>
      <origin
        xyz="0.16893 0.049161 -4.7955E-06"
        rpy="0 0 0" />
      <mass
        value="0.39797" />
      <inertia
        ixx="9.817E-05"
        ixy="-1.072E-06"
        ixz="-3.6619E-11"
        iyy="0.0001041"
        iyz="-2.0315E-11"
        izz="0.00010592" />
    </inertial>
    <visual>
      <origin
        xyz="0 0 0"
        rpy="0 0 0" />
      <!-- <origin
        xyz="0.095 0.04 0"
        rpy="0 1.57 0.131" /> -->
      <geometry>
        <mesh
          filename="package://mini_tail_description/meshes/link3.STL" />
        <!-- <cylinder length="0.23" radius="0.012"/> -->
      </geometry>
      <material
        name="">
        <color
          rgba="0.75294 0.75294 0.75294 1" />
      </material>
    </visual>
    <collision>
      <origin
        xyz="0.095 0.04 0"
        rpy="0 1.57 0.131" />
      <geometry>
        <!-- <mesh
          filename="package://tail_urdf/meshes/link3.STL" /> -->
          <cylinder length="0.23" radius="0.012"/>
      </geometry>
    </collision>
  </link>
  <joint
    name="joint3"
    type="revolute">
    <origin
      xyz="-0.2 0 0"
      rpy="0 0 0" />
    <parent
      link="link2" />
    <child
      link="link3" />
    <axis
      xyz="0 0 1" />
    <dynamics damping="0.01" friction="0.1"/>
    <limit
      lower="0"
      upper="3.6"
      effort="8"
      velocity="12.57" />
  </joint>
  <link name="tail_end">
    <visual>
      <origin rpy="0 0 0" xyz="0 0 0"/>
      <geometry>
        <sphere radius="0.02"/>
      </geometry>
      <!-- <material name="orange"/> -->
    </visual>
    <collision>
      <origin rpy="0 0 0" xyz="0 0 0"/>
      <geometry>
        <sphere radius="0.02"/>
      </geometry>
    </collision>
    <inertial>
      <mass value="0.4"/>
      <inertia ixx="9.600000000000001e-06" ixy="0.0" ixz="0.0" iyy="9.600000000000001e-06" iyz="0.0" izz="9.600000000000001e-06"/>
    </inertial>
  </link>
  <joint name="tail_end_fixed" type="fixed">
    <origin rpy="0 0 0" xyz="0.22 0.06 0"/>
    <parent link="link3"/>
    <child link="tail_end"/>
  </joint>
  <gazebo reference="base_link">
    <mu1>0.6</mu1>
    <mu2>0.6</mu2>
    <self_collide>1</self_collide>
    <material>Gazebo/DarkGrey</material>
    <kp value="1000000.0"/>
    <kd value="100.0"/>
  </gazebo>
  <gazebo reference="link2">
    <mu1>0.6</mu1>
    <mu2>0.6</mu2>
    <self_collide>1</self_collide>
    <material>Gazebo/DarkGrey</material>
    <kp value="1000000.0"/>
    <kd value="100.0"/>
  </gazebo>
  <gazebo reference="link3">
    <mu1>0.6</mu1>
    <mu2>0.6</mu2>
    <self_collide>1</self_collide>
    <material>Gazebo/DarkGrey</material>
    <kp value="1000000.0"/>
    <kd value="100.0"/>
  </gazebo>
<transmission name="tail1">
    <type>transmission_interface/SimpleTransmission</type>
    <joint name="joint1">
      <hardwareInterface>hardware_interface/EffortJointInterface</hardwareInterface>
    </joint>
    <actuator name="joint1_motor">
      <hardwareInterface>hardware_interface/EffortJointInterface</hardwareInterface>
      <mechanicalReduction>1</mechanicalReduction>
    </actuator>
  </transmission>
  <transmission name="tail2">
    <type>transmission_interface/SimpleTransmission</type>
    <joint name="joint2">
      <hardwareInterface>hardware_interface/EffortJointInterface</hardwareInterface>
    </joint>
    <actuator name="joint2_motor">
      <hardwareInterface>hardware_interface/EffortJointInterface</hardwareInterface>
      <mechanicalReduction>1</mechanicalReduction>
    </actuator>
  </transmission>
  <transmission name="tail3">
    <type>transmission_interface/SimpleTransmission</type>
    <joint name="joint3">
      <hardwareInterface>hardware_interface/EffortJointInterface</hardwareInterface>
    </joint>
    <actuator name="joint3_motor">
      <hardwareInterface>hardware_interface/EffortJointInterface</hardwareInterface>
      <mechanicalReduction>1</mechanicalReduction>
    </actuator>
  </transmission>
</robot>

